2021-01-09 18:34:07,898 ERROR: Exception on /user/444 [GET] [in c:\users\racco\miniconda3\lib\site-packages\flask\app.py:1891]
Traceback (most recent call last):
  File "c:\users\racco\miniconda3\lib\site-packages\sqlalchemy\engine\base.py", line 1276, in _execute_context
    self.dialect.do_execute(
  File "c:\users\racco\miniconda3\lib\site-packages\sqlalchemy\engine\default.py", line 609, in do_execute
    cursor.execute(statement, parameters)
sqlite3.OperationalError: no such table: followers

The above exception was the direct cause of the following exception:

Traceback (most recent call last):
  File "c:\users\racco\miniconda3\lib\site-packages\flask\app.py", line 2447, in wsgi_app
    response = self.full_dispatch_request()
  File "c:\users\racco\miniconda3\lib\site-packages\flask\app.py", line 1952, in full_dispatch_request
    rv = self.handle_user_exception(e)
  File "c:\users\racco\miniconda3\lib\site-packages\flask\app.py", line 1821, in handle_user_exception
    reraise(exc_type, exc_value, tb)
  File "c:\users\racco\miniconda3\lib\site-packages\flask\_compat.py", line 39, in reraise
    raise value
  File "c:\users\racco\miniconda3\lib\site-packages\flask\app.py", line 1950, in full_dispatch_request
    rv = self.dispatch_request()
  File "c:\users\racco\miniconda3\lib\site-packages\flask\app.py", line 1936, in dispatch_request
    return self.view_functions[rule.endpoint](**req.view_args)
  File "c:\users\racco\miniconda3\lib\site-packages\flask_login\utils.py", line 272, in decorated_view
    return func(*args, **kwargs)
  File "E:\BSUIR\stp\microblog_\app\routes.py", line 82, in user
    return render_template('user.html', user=user, posts=posts, form=form)
  File "c:\users\racco\miniconda3\lib\site-packages\flask\templating.py", line 137, in render_template
    return _render(
  File "c:\users\racco\miniconda3\lib\site-packages\flask\templating.py", line 120, in _render
    rv = template.render(context)
  File "c:\users\racco\miniconda3\lib\site-packages\jinja2\environment.py", line 1090, in render
    self.environment.handle_exception()
  File "c:\users\racco\miniconda3\lib\site-packages\jinja2\environment.py", line 832, in handle_exception
    reraise(*rewrite_traceback_stack(source=source))
  File "c:\users\racco\miniconda3\lib\site-packages\jinja2\_compat.py", line 28, in reraise
    raise value.with_traceback(tb)
  File "E:\BSUIR\stp\microblog_\app\templates\user.html", line 1, in top-level template code
    {% extends "base.html" %}
  File "E:\BSUIR\stp\microblog_\app\templates\base.html", line 30, in top-level template code
    {% block content %}{% endblock %}
  File "E:\BSUIR\stp\microblog_\app\templates\user.html", line 11, in block "content"
    <p>{{ user.followers.count() }} followers, {{ user.followed.count() }} following.</p>
  File "c:\users\racco\miniconda3\lib\site-packages\sqlalchemy\orm\dynamic.py", line 335, in count
    return self._clone(sess).count()
  File "c:\users\racco\miniconda3\lib\site-packages\sqlalchemy\orm\query.py", line 3803, in count
    return self.from_self(col).scalar()
  File "c:\users\racco\miniconda3\lib\site-packages\sqlalchemy\orm\query.py", line 3523, in scalar
    ret = self.one()
  File "c:\users\racco\miniconda3\lib\site-packages\sqlalchemy\orm\query.py", line 3490, in one
    ret = self.one_or_none()
  File "c:\users\racco\miniconda3\lib\site-packages\sqlalchemy\orm\query.py", line 3459, in one_or_none
    ret = list(self)
  File "c:\users\racco\miniconda3\lib\site-packages\sqlalchemy\orm\query.py", line 3535, in __iter__
    return self._execute_and_instances(context)
  File "c:\users\racco\miniconda3\lib\site-packages\sqlalchemy\orm\query.py", line 3560, in _execute_and_instances
    result = conn.execute(querycontext.statement, self._params)
  File "c:\users\racco\miniconda3\lib\site-packages\sqlalchemy\engine\base.py", line 1011, in execute
    return meth(self, multiparams, params)
  File "c:\users\racco\miniconda3\lib\site-packages\sqlalchemy\sql\elements.py", line 298, in _execute_on_connection
    return connection._execute_clauseelement(self, multiparams, params)
  File "c:\users\racco\miniconda3\lib\site-packages\sqlalchemy\engine\base.py", line 1124, in _execute_clauseelement
    ret = self._execute_context(
  File "c:\users\racco\miniconda3\lib\site-packages\sqlalchemy\engine\base.py", line 1316, in _execute_context
    self._handle_dbapi_exception(
  File "c:\users\racco\miniconda3\lib\site-packages\sqlalchemy\engine\base.py", line 1510, in _handle_dbapi_exception
    util.raise_(
  File "c:\users\racco\miniconda3\lib\site-packages\sqlalchemy\util\compat.py", line 182, in raise_
    raise exception
  File "c:\users\racco\miniconda3\lib\site-packages\sqlalchemy\engine\base.py", line 1276, in _execute_context
    self.dialect.do_execute(
  File "c:\users\racco\miniconda3\lib\site-packages\sqlalchemy\engine\default.py", line 609, in do_execute
    cursor.execute(statement, parameters)
sqlalchemy.exc.OperationalError: (sqlite3.OperationalError) no such table: followers
[SQL: SELECT count(*) AS count_1 
FROM (SELECT user.id AS user_id, user.username AS user_username, user.email AS user_email, user.password_hash AS user_password_hash, user.about_me AS user_about_me, user.last_seen AS user_last_seen 
FROM user, followers 
WHERE followers.followed_id = ? AND followers.follower_id = user.id) AS anon_1]
[parameters: (8,)]
(Background on this error at: http://sqlalche.me/e/13/e3q8)
2021-01-09 18:35:28,667 INFO: Microblog startup [in E:\BSUIR\stp\microblog_\app\__init__.py:43]
2021-01-09 18:35:39,303 INFO: Microblog startup [in E:\BSUIR\stp\microblog_\app\__init__.py:43]
2021-01-09 18:35:47,718 INFO: Microblog startup [in E:\BSUIR\stp\microblog_\app\__init__.py:43]
